Workbook

Sheet README
A1: cohort100-ab — FINAL results (both batches)
A3: Status: FINAL. Pre-registered analysis (section 10 step 7) on both batches: eval-b1 + eval-b2 = 100 tasks, T_dec from dec-1. Supersedes eval-b1-interim-tables.xlsx (D3).
A5: Design: 100 tasks, each run under BOTH configs (B0-Sequential, A1-Parallel) back to back = 200 arm results.
A6: 'Arm results' has one row per task x arm (200 rows). 'Paired' has one row per task (100 rows): speedups and other B0-vs-A1 comparisons need both arms, so they live there, computed by formula from 'Arm results'.
A7: Arms that did not succeed: easy2_17 A1. Per prereg §8 such a task counts for completion and accuracy but not for speedup (n = 99 tasks in S).
A9: Colour key: blue = value taken from run records or the analysis JSON (hardcoded, source noted); black = formula within the sheet; green = formula referencing another sheet.
A10: The Estimates sheet reports the pre-registered script's numbers; 'Workbook check' recomputes point estimates with formulas and should agree. Bootstrap CIs cannot be formulas and come from the script.
A12: Provenance
A13: Run eval-b1: rows.jsonl sha256 e84d60036a36982f…, grades.json sha256 1392c8203e0fa056… (upstream LongCoT verifier)
A14: Run eval-b2: rows.jsonl sha256 0cfba210f1bdd8dd…, grades.json sha256 df64bf0acea1e8a4… (upstream LongCoT verifier)
A15: T_dec dec-1: rows.jsonl sha256 2de482d7a468450a…
A16: Analysis JSON sha256 b65c7c7a5deb39f6…
... A20: Built by data/cohort100_ab/analysis/build_eval_xlsx.py. Column definitions: Definitions sheet.

Sheet Definitions
A1: Sheet | B1: Column | C1: Definition
A2: All | B2: (design) | C2: 100 tasks in two seeded batches of 50; every task ran under BOTH configs (B0-Sequential and A1-Parallel), back to back: 200 arm results, 910 subtasks per arm, 1824 model calls in total (retries included). Speedups are paired within a task.
A3: All | B3: B0 / A1 | C3: B0-Sequential: one Step Functions task per subtask, chained in a fixed topological order. A1-Parallel: every subtask starts at once and waits for its own predecessors, then calls the model. Same functions, prompts, model and settings.
A4: Arm results | B4: Batch | C4: 1 = eval-b1, 2 = eval-b2.
A5: Arm results | B5: Pos | C5: The task's run order within its batch (seeded, 1-50); shared by its two arm rows.
A6: Arm results | B6: Task | C6: LongCoT task ID (last component).
A7: Arm results | B7: Arm | C7: Config for this row: B0 (sequential) or A1 (parallel).
A8: Arm results | B8: Ran | C8: Whether this arm ran 1st or 2nd for the task (alternates by position).
A9: Arm results | B9: Template | C9: One of the 10 DAG shapes; the DAG is identical for every task of a template.
A10: Arm results | B10: Difficulty | C10: LongCoT difficulty label (easy / medium / hard).
A11: Arm results | B11: Exposed | C11: 1 if the task was seen during development (all easy tasks + hard2_0).
A12: Arm results | B12: Flagged impossible | C12: 1 if the task contains an impossible conditional.
... A67: Cost | B67: C_LLM (tokens x list price) | C67: Reconciliation: recomputed from token counts at gpt-5.2 list prices; compare with the reported C_LLM.

Sheet Arm results
A1: Batch | B1: Pos | C1: Task | D1: Arm | E1: Ran | F1: Template | G1: Difficulty | H1: Exposed | I1: Flagged impossible | J1: easy2 policy | K1: N | L1: D | M1: W | N1: Status | O1: T_exec (s) | P1: Node-time sum (s) | Q1: Dep. critical path (s) | R1: Wave-barrier time (s) | S1: Replay (dep.) | T1: Replay (wave) | U1: Overhead (s) | V1: Dependency wait (s) | W1: Cold starts | X1: Cold init (s) | Y1: Model calls | Z1: Retries | AA1: 429 replies | AB1: Truncated attempts | AC1: Input tok | AD1: Output tok | AE1: Reasoning tok | AF1: C_LLM ($) | AG1: C_Lambda ($) | AH1: C_StepFunctions ($) | AI1: C_Total ($) | AJ1: Correct | AK1: no_match
A2: 1 | B2: 1 | C2: easy1_49 | D2: B0 | E2: 1st | F2: easy1 | G2: easy | H2: 1 | I2: 0 | J2: 0 | K2: 5 | L2: 4 | M2: 2 | N2: SUCCEEDED | O2: 59.429 | P2: 58.039828 | Q2: 42.633723 | R2: 53.587953 | S2: =IF(N2="SUCCEEDED",P2/Q2,"") | T2: =IF(N2="SUCCEEDED",P2/R2,"") | U2: =IF(N2="SUCCEEDED",IF(D2="B0",O2-P2,O2-Q2),"") | V2: 0.22975016 | W2: 0 | X2: 0 | Y2: 5 | Z2: 0 | AA2: 0 | AB2: 0 | AC2: 2109 | AD2: 4101 | AE2: 3893 | AF2: 0.06110475 | AG2: 0.00039320863 | AH2: 0.000125 | AI2: =AF2+AG2+AH2 | AJ2: 1
A3: 1 | B3: 1 | C3: easy1_49 | D3: A1 | E3: 2nd | F3: easy1 | G3: easy | H3: 1 | I3: 0 | J3: 0 | K3: 5 | L3: 4 | M3: 2 | N3: SUCCEEDED | O3: 36.708 | P3: 52.126326 | Q3: 36.239802 | R3: 48.068455 | S3: =IF(N3="SUCCEEDED",P3/Q3,"") | T3: =IF(N3="SUCCEEDED",P3/R3,"") | U3: =IF(N3="SUCCEEDED",IF(D3="B0",O3-P3,O3-Q3),"") | V3: 41.2638 | W3: 0 | X3: 0 | Y3: 5 | Z3: 0 | AA3: 0 | AB3: 0 | AC3: 2109 | AD3: 3198 | AE3: 2990 | AF3: 0.04846275 | AG3: 0.0006266898 | AH3: 0.00015 | AI3: =AF3+AG3+AH3 | AJ3: 1
A4: 1 | B4: 2 | C4: med1_37 | D4: A1 | E4: 1st | F4: med1 | G4: medium | H4: 0 | I4: 0 | J4: 0 | K4: 9 | L4: 4 | M4: 5 | N4: SUCCEEDED | O4: 122.114 | P4: 197.73544 | Q4: 121.39396 | R4: 152.91363 | S4: =IF(N4="SUCCEEDED",P4/Q4,"") | T4: =IF(N4="SUCCEEDED",P4/R4,"") | U4: =IF(N4="SUCCEEDED",IF(D4="B0",O4-P4,O4-Q4),"") | V4: 113.39268 | W4: 0 | X4: 0 | Y4: 9 | Z4: 0 | AA4: 0 | AB4: 0 | AC4: 3774 | AD4: 13615 | AE4: 13310 | AF4: 0.1972145 | AG4: 0.0020827504 | AH4: 0.00025 | AI4: =AF4+AG4+AH4 | AJ4: 0
A5: 1 | B5: 2 | C5: med1_37 | D5: B0 | E5: 2nd | F5: med1 | G5: medium | H5: 0 | I5: 0 | J5: 0 | K5: 9 | L5: 4 | M5: 5 | N5: SUCCEEDED | O5: 182.917 | P5: 180.30539 | Q5: 102.92442 | R5: 129.7843 | S5: =IF(N5="SUCCEEDED",P5/Q5,"") | T5: =IF(N5="SUCCEEDED",P5/R5,"") | U5: =IF(N5="SUCCEEDED",IF(D5="B0",O5-P5,O5-Q5),"") | V5: 0.46329975 | W5: 0 | X5: 0 | Y5: 9 | Z5: 0 | AA5: 0 | AB5: 0 | AC5: 3763 | AD5: 12336 | AE5: 12033 | AF5: 0.17928925 | AG5: 0.0012141327 | AH5: 0.000225 | AI5: =AF5+AG5+AH5 | AJ5: 0
A6: 1 | B6: 3 | C6: easy1_12 | D6: B0 | E6: 1st | F6: easy1 | G6: easy | H6: 1 | I6: 0 | J6: 0 | K6: 5 | L6: 4 | M6: 2 | N6: SUCCEEDED | O6: 100.044 | P6: 98.636461 | Q6: 70.927945 | R6: 89.038457 | S6: =IF(N6="SUCCEEDED",P6/Q6,"") | T6: =IF(N6="SUCCEEDED",P6/R6,"") | U6: =IF(N6="SUCCEEDED",IF(D6="B0",O6-P6,O6-Q6),"") | V6: 0.23921204 | W6: 0 | X6: 0 | Y6: 5 | Z6: 0 | AA6: 0 | AB6: 0 | AC6: 2228 | AD6: 7183 | AE6: 6930 | AF6: 0.104461 | AG6: 0.00066386331 | AH6: 0.000125 | AI6: =AF6+AG6+AH6 | AJ6: 0
A7: 1 | B7: 3 | C7: easy1_12 | D7: A1 | E7: 2nd | F7: easy1 | G7: easy | H7: 1 | I7: 0 | J7: 0 | K7: 5 | L7: 4 | M7: 2 | N7: SUCCEEDED | O7: 99.218 | P7: 128.74502 | Q7: 98.240722 | R7: 121.0156 | S7: =IF(N7="SUCCEEDED",P7/Q7,"") | T7: =IF(N7="SUCCEEDED",P7/R7,"") | U7: =IF(N7="SUCCEEDED",IF(D7="B0",O7-P7,O7-Q7),"") | V7: 65.090665 | W7: 0 | X7: 0 | Y7: 5 | Z7: 0 | AA7: 0 | AB7: 0 | AC7: 2218 | AD7: 8320 | AE7: 8067 | AF7: 0.1203615 | AG7: 0.0012968731 | AH7: 0.00015 | AI7: =AF7+AG7+AH7 | AJ7: 0
A8: 1 | B8: 4 | C8: easy2_26 | D8: A1 | E8: 1st | F8: easy2 | G8: easy | H8: 1 | I8: 0 | J8: 1 | K8: 5 | L8: 4 | M8: 2 | N8: SUCCEEDED | O8: 115.797 | P8: 121.17054 | Q8: 114.72702 | R8: 114.72702 | S8: =IF(N8="SUCCEEDED",P8/Q8,"") | T8: =IF(N8="SUCCEEDED",P8/R8,"") | U8: =IF(N8="SUCCEEDED",IF(D8="B0",O8-P8,O8-Q8),"") | V8: 200.6791 | W8: 0 | X8: 0 | Y8: 5 | Z8: 0 | AA8: 0 | AB8: 0 | AC8: 3398 | AD8: 7219 | AE8: 5918 | AF8: 0.1070125 | AG8: 0.0021502374 | AH8: 0.00015 | AI8: =AF8+AG8+AH8 | AJ8: 0 | AK8: no
A9: 1 | B9: 4 | C9: easy2_26 | D9: B0 | E9: 2nd | F9: easy2 | G9: easy | H9: 1 | I9: 0 | J9: 1 | K9: 5 | L9: 4 | M9: 2 | N9: SUCCEEDED | O9: 108.818 | P9: 107.37538 | Q9: 101.40454 | R9: 101.40454 | S9: =IF(N9="SUCCEEDED",P9/Q9,"") | T9: =IF(N9="SUCCEEDED",P9/R9,"") | U9: =IF(N9="SUCCEEDED",IF(D9="B0",O9-P9,O9-Q9),"") | V9: 0.23131108 | W9: 0 | X9: 0 | Y9: 5 | Z9: 0 | AA9: 0 | AB9: 0 | AC9: 3923 | AD9: 7927 | AE9: 6097 | AF9: 0.11784325 | AG9: 0.00072203694 | AH9: 0.000125 | AI9: =AF9+AG9+AH9 | AJ9: 0 | AK9: no
A10: 1 | B10: 5 | C10: hard1_11 | D10: B0 | E10: 1st | F10: hard1 | G10: hard | H10: 0 | I10: 0 | J10: 0 | K10: 16 | L10: 9 | M10: 5 | N10: SUCCEEDED | O10: 433.648 | P10: 428.28737 | Q10: 324.38253 | R10: 367.92133 | S10: =IF(N10="SUCCEEDED",P10/Q10,"") | T10: =IF(N10="SUCCEEDED",P10/R10,"") | U10: =IF(N10="SUCCEEDED",IF(D10="B0",O10-P10,O10-Q10),"") | V10: 1.0728209 | W10: 1 | X10: 0.54327 | Y10: 16 | Z10: 0 | AA10: 0 | AB10: 0 | AC10: 11523 | AD10: 26771 | AE10: 25960 | AF10: 0.39495925 | AG10: 0.0028806944 | AH10: 0.0004 | AI10: =AF10+AG10+AH10 | AJ10: 0
A11: 1 | B11: 5 | C11: hard1_11 | D11: A1 | E11: 2nd | F11: hard1 | G11: hard | H11: 0 | I11: 0 | J11: 0 | K11: 16 | L11: 9 | M11: 5 | N11: SUCCEEDED | O11: 266.311 | P11: 362.99699 | Q11: 264.40329 | R11: 288.28792 | S11: =IF(N11="SUCCEEDED",P11/Q11,"") | T11: =IF(N11="SUCCEEDED",P11/R11,"") | U11: =IF(N11="SUCCEEDED",IF(D11="B0",O11-P11,O11-Q11),"") | V11: 967.20069 | W11: 0 | X11: 0 | Y11: 16 | Z11: 0 | AA11: 0 | AB11: 0 | AC11: 11574 | AD11: 24578 | AE11: 23693 | AF11: 0.3643465 | AG11: 0.0088827377 | AH11: 0.000425 | AI11: =AF11+AG11+AH11 | AJ11: 0
A12: 1 | B12: 6 | C12: easy1_11 | D12: A1 | E12: 1st | F12: easy1 | G12: easy | H12: 1 | I12: 0 | J12: 0 | K12: 5 | L12: 4 | M12: 2 | N12: SUCCEEDED | O12: 44.15 | P12: 51.897578 | Q12: 43.171277 | R12: 43.283992 | S12: =IF(N12="SUCCEEDED",P12/Q12,"") | T12: =IF(N12="SUCCEEDED",P12/R12,"") | U12: =IF(N12="SUCCEEDED",IF(D12="B0",O12-P12,O12-Q12),"") | V12: 63.286016 | W12: 0 | X12: 0 | Y12: 5 | Z12: 0 | AA12: 0 | AB12: 0 | AC12: 2355 | AD12: 3377 | AE12: 3063 | AF12: 0.05139925 | AG12: 0.00077216386 | AH12: 0.00015 | AI12: =AF12+AG12+AH12 | AJ12: 0
A13: 1 | B13: 6 | C13: easy1_11 | D13: B0 | E13: 2nd | F13: easy1 | G13: easy | H13: 1 | I13: 0 | J13: 0 | K13: 5 | L13: 4 | M13: 2 | N13: SUCCEEDED | O13: 71.108 | P13: 69.787754 | Q13: 55.720182 | R13: 58.720812 | S13: =IF(N13="SUCCEEDED",P13/Q13,"") | T13: =IF(N13="SUCCEEDED",P13/R13,"") | U13: =IF(N13="SUCCEEDED",IF(D13="B0",O13-P13,O13-Q13),"") | V13: 0.21768236 | W13: 0 | X13: 0 | Y13: 5 | Z13: 0 | AA13: 0 | AB13: 0 | AC13: 2365 | AD13: 4087 | AE13: 3771 | AF13: 0.06135675 | AG13: 0.00047084235 | AH13: 0.000125 | AI13: =AF13+AG13+AH13 | AJ13: 0
A14: 1 | B14: 7 | C14: easy1_3 | D14: B0 | E14: 1st | F14: easy1 | G14: easy | H14: 1 | I14: 0 | J14: 0 | K14: 5 | L14: 4 | M14: 2 | N14: SUCCEEDED | O14: 42.214 | P14: 40.851024 | Q14: 30.673031 | R14: 37.81774 | S14: =IF(N14="SUCCEEDED",P14/Q14,"") | T14: =IF(N14="SUCCEEDED",P14/R14,"") | U14: =IF(N14="SUCCEEDED",IF(D14="B0",O14-P14,O14-Q14),"") | V14: 0.24131989 | W14: 0 | X14: 0 | Y14: 5 | Z14: 0 | AA14: 0 | AB14: 0 | AC14: 2002 | AD14: 2550 | AE14: 2395 | AF14: 0.0392035 | AG14: 0.00027813472 | AH14: 0.000125 | AI14: =AF14+AG14+AH14 | AJ14: 0
A15: 1 | B15: 7 | C15: easy1_3 | D15: A1 | E15: 2nd | F15: easy1 | G15: easy | H15: 1 | I15: 0 | J15: 0 | K15: 5 | L15: 4 | M15: 2 | N15: SUCCEEDED | O15: 36.987 | P15: 47.452363 | Q15: 36.462804 | R15: 44.181545 | S15: =IF(N15="SUCCEEDED",P15/Q15,"") | T15: =IF(N15="SUCCEEDED",P15/R15,"") | U15: =IF(N15="SUCCEEDED",IF(D15="B0",O15-P15,O15-Q15),"") | V15: 28.641293 | W15: 0 | X15: 0 | Y15: 5 | Z15: 0 | AA15: 0 | AB15: 0 | AC15: 1987 | AD15: 2813 | AE15: 2658 | AF15: 0.04285925 | AG15: 0.00051119588 | AH15: 0.00015 | AI15: =AF15+AG15+AH15 | AJ15: 0
A16: 1 | B16: 8 | C16: easy2_18 | D16: A1 | E16: 1st | F16: easy2 | G16: easy | H16: 1 | I16: 0 | J16: 1 | K16: 5 | L16: 4 | M16: 2 | N16: SUCCEEDED | O16: 124.249 | P16: 129.2035 | Q16: 123.24268 | R16: 123.24268 | S16: =IF(N16="SUCCEEDED",P16/Q16,"") | T16: =IF(N16="SUCCEEDED",P16/R16,"") | U16: =IF(N16="SUCCEEDED",IF(D16="B0",O16-P16,O16-Q16),"") | V16: 242.67972 | W16: 0 | X16: 0 | Y16: 5 | Z16: 0 | AA16: 0 | AB16: 0 | AC16: 2854 | AD16: 9565 | AE16: 8804 | AF16: 0.1389045 | AG16: 0.0024839391 | AH16: 0.00015 | AI16: =AF16+AG16+AH16 | AJ16: 0 | AK16: yes
A17: 1 | B17: 8 | C17: easy2_18 | D17: B0 | E17: 2nd | F17: easy2 | G17: easy | H17: 1 | I17: 0 | J17: 1 | K17: 5 | L17: 4 | M17: 2 | N17: SUCCEEDED | O17: 113.136 | P17: 111.81517 | Q17: 104.1266 | R17: 104.1266 | S17: =IF(N17="SUCCEEDED",P17/Q17,"") | T17: =IF(N17="SUCCEEDED",P17/R17,"") | U17: =IF(N17="SUCCEEDED",IF(D17="B0",O17-P17,O17-Q17),"") | V17: 0.23359776 | W17: 0 | X17: 0 | Y17: 5 | Z17: 0 | AA17: 0 | AB17: 0 | AC17: 2851 | AD17: 7681 | AE17: 6908 | AF17: 0.11252325 | AG17: 0.00075132375 | AH17: 0.000125 | AI17: =AF17+AG17+AH17 | AJ17: 1 | AK17: no
A18: 1 | B18: 9 | C18: easy2_25 | D18: B0 | E18: 1st | F18: easy2 | G18: easy | H18: 1 | I18: 0 | J18: 1 | K18: 5 | L18: 4 | M18: 2 | N18: SUCCEEDED | O18: 134.321 | P18: 132.93795 | Q18: 127.75771 | R18: 127.75771 | S18: =IF(N18="SUCCEEDED",P18/Q18,"") | T18: =IF(N18="SUCCEEDED",P18/R18,"") | U18: =IF(N18="SUCCEEDED",IF(D18="B0",O18-P18,O18-Q18),"") | V18: 0.25660253 | W18: 0 | X18: 0 | Y18: 5 | Z18: 0 | AA18: 0 | AB18: 0 | AC18: 2557 | AD18: 9053 | AE18: 8544 | AF18: 0.13121675 | AG18: 0.00089257779 | AH18: 0.000125 | AI18: =AF18+AG18+AH18 | AJ18: 0 | AK18: yes
A19: 1 | B19: 9 | C19: easy2_25 | D19: A1 | E19: 2nd | F19: easy2 | G19: easy | H19: 1 | I19: 0 | J19: 1 | K19: 5 | L19: 4 | M19: 2 | N19: SUCCEEDED | O19: 124.854 | P19: 128.21026 | Q19: 123.83688 | R19: 123.83688 | S19: =IF(N19="SUCCEEDED",P19/Q19,"") | T19: =IF(N19="SUCCEEDED",P19/R19,"") | U19: =IF(N19="SUCCEEDED",IF(D19="B0",O19-P19,O19-Q19),"") | V19: 152.79699 | W19: 0 | X19: 0 | Y19: 5 | Z19: 0 | AA19: 0 | AB19: 0 | AC19: 2594 | AD19: 9094 | AE19: 8556 | AF19: 0.1318555 | AG19: 0.0018779494 | AH19: 0.00015 | AI19: =AF19+AG19+AH19 | AJ19: 0 | AK19: yes
A20: 1 | B20: 10 | C20: protein_1CAD_query_2_mask_4 | D20: A1 | E20: 1st | F20: hard4 | G20: hard | H20: 0 | I20: 0 | J20: 0 | K20: 6 | L20: 5 | M20: 2 | N20: SUCCEEDED | O20: 129.522 | P20: 134.46337 | Q20: 128.20941 | R20: 128.20941 | S20: =IF(N20="SUCCEEDED",P20/Q20,"") | T20: =IF(N20="SUCCEEDED",P20/R20,"") | U20: =IF(N20="SUCCEEDED",IF(D20="B0",O20-P20,O20-Q20),"") | V20: 204.37151 | W20: 0 | X20: 0 | Y20: 6 | Z20: 0 | AA20: 0 | AB20: 0 | AC20: 87942 | AD20: 10970 | AE20: 10769 | AF20: 0.3074785 | AG20: 0.0022640846 | AH20: 0.000175 | AI20: =AF20+AG20+AH20 | AJ20: 0
A21: 1 | B21: 10 | C21: protein_1CAD_query_2_mask_4 | D21: B0 | E21: 2nd | F21: hard4 | G21: hard | H21: 0 | I21: 0 | J21: 0 | K21: 6 | L21: 5 | M21: 2 | N21: SUCCEEDED | O21: 73.91 | P21: 72.102682 | Q21: 66.037498 | R21: 66.037498 | S21: =IF(N21="SUCCEEDED",P21/Q21,"") | T21: =IF(N21="SUCCEEDED",P21/R21,"") | U21: =IF(N21="SUCCEEDED",IF(D21="B0",O21-P21,O21-Q21),"") | V21: 0.4560082 | W21: 0 | X21: 0 | Y21: 6 | Z21: 0 | AA21: 0 | AB21: 0 | AC21: 87972 | AD21: 5543 | AE21: 5322 | AF21: 0.231553 | AG21: 0.00048876244 | AH21: 0.00015 | AI21: =AF21+AG21+AH21 | AJ21: 0
A22: 1 | B22: 11 | C22: med2_22 | D22: B0 | E22: 1st | F22: med2 | G22: medium | H22: 0 | I22: 0 | J22: 0 | K22: 9 | L22: 4 | M22: 5 | N22: SUCCEEDED | O22: 204.956 | P22: 202.51278 | Q22: 129.69518 | R22: 151.60579 | S22: =IF(N22="SUCCEEDED",P22/Q22,"") | T22: =IF(N22="SUCCEEDED",P22/R22,"") | U22: =IF(N22="SUCCEEDED",IF(D22="B0",O22-P22,O22-Q22),"") | V22: 0.41191268 | W22: 1 | X22: 0.87451 | Y22: 9 | Z22: 0 | AA22: 0 | AB22: 0 | AC22: 4075 | AD22: 14078 | AE22: 13632 | AF22: 0.20422325 | AG22: 0.0013665868 | AH22: 0.000225 | AI22: =AF22+AG22+AH22 | AJ22: 0
A23: 1 | B23: 11 | C23: med2_22 | D23: A1 | E23: 2nd | F23: med2 | G23: medium | H23: 0 | I23: 0 | J23: 0 | K23: 9 | L23: 4 | M23: 5 | N23: SUCCEEDED | O23: 108.834 | P23: 176.64473 | Q23: 108.07159 | R23: 137.1519 | S23: =IF(N23="SUCCEEDED",P23/Q23,"") | T23: =IF(N23="SUCCEEDED",P23/R23,"") | U23: =IF(N23="SUCCEEDED",IF(D23="B0",O23-P23,O23-Q23),"") | V23: 109.65754 | W23: 0 | X23: 0 | Y23: 9 | Z23: 0 | AA23: 0 | AB23: 0 | AC23: 4082 | AD23: 12461 | AE23: 12017 | AF23: 0.1815975 | AG23: 0.0019175362 | AH23: 0.00025 | AI23: =AF23+AG23+AH23 | AJ23: 0
A24: 1 | B24: 12 | C24: protein_1CRN_query_3_mask_4 | D24: A1 | E24: 1st | F24: hard4 | G24: hard | H24: 0 | I24: 0 | J24: 0 | K24: 6 | L24: 5 | M24: 2 | N24: SUCCEEDED | O24: 159.218 | P24: 164.76006 | Q24: 158.07107 | R24: 158.07107 | S24: =IF(N24="SUCCEEDED",P24/Q24,"") | T24: =IF(N24="SUCCEEDED",P24/R24,"") | U24: =IF(N24="SUCCEEDED",IF(D24="B0",O24-P24,O24-Q24),"") | V24: 191.68463 | W24: 0 | X24: 0 | Y24: 6 | Z24: 0 | AA24: 0 | AB24: 0 | AC24: 69776 | AD24: 13308 | AE24: 13109 | AF24: 0.30842 | AG24: 0.0023820252 | AH24: 0.000175 | AI24: =AF24+AG24+AH24 | AJ24: 0
A25: 1 | B25: 12 | C25: protein_1CRN_query_3_mask_4 | D25: B0 | E25: 2nd | F25: hard4 | G25: hard | H25: 0 | I25: 0 | J25: 0 | K25: 6 | L25: 5 | M25: 2 | N25: SUCCEEDED | O25: 160.293 | P25: 158.41853 | Q25: 149.9939 | R25: 149.9939 | S25: =IF(N25="SUCCEEDED",P25/Q25,"") | T25: =IF(N25="SUCCEEDED",P25/R25,"") | U25: =IF(N25="SUCCEEDED",IF(D25="B0",O25-P25,O25-Q25),"") | V25: 0.48751569 | W25: 0 | X25: 0 | Y25: 6 | Z25: 0 | AA25: 0 | AB25: 0 | AC25: 69827 | AD25: 11783 | AE25: 11564 | AF25: 0.28715925 | AG25: 0.0010647387 | AH25: 0.00015 | AI25: =AF25+AG25+AH25 | AJ25: 0
A26: 1 | B26: 13 | C26: med1_3 | D26: B0 | E26: 1st | F26: med1 | G26: medium | H26: 0 | I26: 0 | J26: 0 | K26: 9 | L26: 4 | M26: 5 | N26: SUCCEEDED | O26: 221.482 | P26: 219.02295 | Q26: 128.50827 | R26: 145.36717 | S26: =IF(N26="SUCCEEDED",P26/Q26,"") | T26: =IF(N26="SUCCEEDED",P26/R26,"") | U26: =IF(N26="SUCCEEDED",IF(D26="B0",O26-P26,O26-Q26),"") | V26: 0.44644475 | W26: 0 | X26: 0 | Y26: 9 | Z26: 0 | AA26: 0 | AB26: 0 | AC26: 3888 | AD26: 13368 | AE26: 13024 | AF26: 0.193956 | AG26: 0.0014716807 | AH26: 0.000225 | AI26: =AF26+AG26+AH26 | AJ26: 1
A27: 1 | B27: 13 | C27: med1_3 | D27: A1 | E27: 2nd | F27: med1 | G27: medium | H27: 0 | I27: 0 | J27: 0 | K27: 9 | L27: 4 | M27: 5 | N27: SUCCEEDED | O27: 116.44 | P27: 184.10856 | Q27: 115.64018 | R27: 123.87355 | S27: =IF(N27="SUCCEEDED",P27/Q27,"") | T27: =IF(N27="SUCCEEDED",P27/R27,"") | U27: =IF(N27="SUCCEEDED",IF(D27="B0",O27-P27,O27-Q27),"") | V27: 135.60064 | W27: 0 | X27: 0 | Y27: 9 | Z27: 0 | AA27: 0 | AB27: 0 | AC27: 3866 | AD27: 11061 | AE27: 10739 | AF27: 0.1616195 | AG27: 0.0021399107 | AH27: 0.00025 | AI27: =AF27+AG27+AH27 | AJ27: 0
A28: 1 | B28: 14 | C28: protein_1PGA_query_6_mask_2 | D28: A1 | E28: 1st | F28: med4 | G28: medium | H28: 0 | I28: 0 | J28: 0 | K28: 6 | L28: 5 | M28: 2 | N28: SUCCEEDED | O28: 110.564 | P28: 115.22525 | Q28: 109.49601 | R28: 109.49601 | S28: =IF(N28="SUCCEEDED",P28/Q28,"") | T28: =IF(N28="SUCCEEDED",P28/R28,"") | U28: =IF(N28="SUCCEEDED",IF(D28="B0",O28-P28,O28-Q28),"") | V28: 209.46656 | W28: 0 | X28: 0 | Y28: 6 | Z28: 0 | AA28: 0 | AB28: 0 | AC28: 94700 | AD28: 8932 | AE28: 8728 | AF28: 0.290773 | AG28: 0.0021697908 | AH28: 0.000175 | AI28: =AF28+AG28+AH28 | AJ28: 0
A29: 1 | B29: 14 | C29: protein_1PGA_query_6_mask_2 | D29: B0 | E29: 2nd | F29: med4 | G29: medium | H29: 0 | I29: 0 | J29: 0 | K29: 6 | L29: 5 | M29: 2 | N29: SUCCEEDED | O29: 132.47 | P29: 130.73568 | Q29: 123.29208 | R29: 123.29208 | S29: =IF(N29="SUCCEEDED",P29/Q29,"") | T29: =IF(N29="SUCCEEDED",P29/R29,"") | U29: =IF(N29="SUCCEEDED",IF(D29="B0",O29-P29,O29-Q29),"") | V29: 0.48782754 | W29: 0 | X29: 0 | Y29: 6 | Z29: 0 | AA29: 0 | AB29: 0 | AC29: 94775 | AD29: 9905 | AE29: 9685 | AF29: 0.30452625 | AG29: 0.00087997773 | AH29: 0.00015 | AI29: =AF29+AG29+AH29 | AJ29: 0
A30: 1 | B30: 15 | C30: med3_45 | D30: B0 | E30: 1st | F30: med3 | G30: medium | H30: 0 | I30: 0 | J30: 0 | K30: 11 | L30: 6 | M30: 2 | N30: SUCCEEDED | O30: 322.878 | P30: 319.61176 | Q30: 189.31645 | R30: 229.33812 | S30: =IF(N30="SUCCEEDED",P30/Q30,"") | T30: =IF(N30="SUCCEEDED",P30/R30,"") | U30: =IF(N30="SUCCEEDED",IF(D30="B0",O30-P30,O30-Q30),"") | V30: 0.71941566 | W30: 0 | X30: 0 | Y30: 11 | Z30: 0 | AA30: 0 | AB30: 0 | AC30: 6158 | AD30: 22101 | AE30: 21673 | AF30: 0.3201905 | AG30: 0.0021454574 | AH30: 0.000275 | AI30: =AF30+AG30+AH30 | AJ30: 0
A31: 1 | B31: 15 | C31: med3_45 | D31: A1 | E31: 2nd | F31: med3 | G31: medium | H31: 0 | I31: 0 | J31: 0 | K31: 11 | L31: 6 | M31: 2 | N31: SUCCEEDED | O31: 151.815 | P31: 270.701 | Q31: 150.40731 | R31: 173.16112 | S31: =IF(N31="SUCCEEDED",P31/Q31,"") | T31: =IF(N31="SUCCEEDED",P31/R31,"") | U31: =IF(N31="SUCCEEDED",IF(D31="B0",O31-P31,O31-Q31),"") | V31: 509.70217 | W31: 0 | X31: 0 | Y31: 11 | Z31: 0 | AA31: 0 | AB31: 0 | AC31: 6196 | AD31: 18824 | AE31: 18380 | AF31: 0.274379 | AG31: 0.0052125727 | AH31: 0.0003 | AI31: =AF31+AG31+AH31 | AJ31: 0
A32: 1 | B32: 16 | C32: easy2_8 | D32: A1 | E32: 1st | F32: easy2 | G32: easy | H32: 1 | I32: 0 | J32: 1 | K32: 5 | L32: 4 | M32: 2 | N32: SUCCEEDED | O32: 106.767 | P32: 111.59521 | Q32: 105.92078 | R32: 105.92078 | S32: =IF(N32="SUCCEEDED",P32/Q32,"") | T32: =IF(N32="SUCCEEDED",P32/R32,"") | U32: =IF(N32="SUCCEEDED",IF(D32="B0",O32-P32,O32-Q32),"") | V32: 167.21444 | W32: 0 | X32: 0 | Y32: 5 | Z32: 0 | AA32: 0 | AB32: 0 | AC32: 2370 | AD32: 8060 | AE32: 7723 | AF32: 0.1169875 | AG32: 0.0018633426 | AH32: 0.00015 | AI32: =AF32+AG32+AH32 | AJ32: 0 | AK32: yes
A33: 1 | B33: 16 | C33: easy2_8 | D33: B0 | E33: 2nd | F33: easy2 | G33: easy | H33: 1 | I33: 0 | J33: 1 | K33: 5 | L33: 4 | M33: 2 | N33: SUCCEEDED | O33: 118.548 | P33: 117.18541 | Q33: 114.13657 | R33: 114.13657 | S33: =IF(N33="SUCCEEDED",P33/Q33,"") | T33: =IF(N33="SUCCEEDED",P33/R33,"") | U33: =IF(N33="SUCCEEDED",IF(D33="B0",O33-P33,O33-Q33),"") | V33: 0.24677324 | W33: 0 | X33: 0 | Y33: 5 | Z33: 0 | AA33: 0 | AB33: 0 | AC33: 2427 | AD33: 8085 | AE33: 7716 | AF33: 0.11743725 | AG33: 0.0007872906 | AH33: 0.000125 | AI33: =AF33+AG33+AH33 | AJ33: 0 | AK33: yes
A34: 1 | B34: 17 | C34: hard2_20 | D34: B0 | E34: 1st | F34: hard2 | G34: hard | H34: 0 | I34: 1 | J34: 0 | K34: 16 | L34: 10 | M34: 5 | N34: SUCCEEDED | O34: 322.778 | P34: 318.1067 | Q34: 263.71765 | R34: 274.23152 | S34: =IF(N34="SUCCEEDED",P34/Q34,"") | T34: =IF(N34="SUCCEEDED",P34/R34,"") | U34: =IF(N34="SUCCEEDED",IF(D34="B0",O34-P34,O34-Q34),"") | V34: 1.0327988 | W34: 0 | X34: 0 | Y34: 16 | Z34: 0 | AA34: 0 | AB34: 0 | AC34: 8490 | AD34: 25099 | AE34: 24456 | AF34: 0.3662435 | AG34: 0.0021422974 | AH34: 0.0004 | AI34: =AF34+AG34+AH34 | AJ34: 0
A35: 1 | B35: 17 | C35: hard2_20 | D35: A1 | E35: 2nd | F35: hard2 | G35: hard | H35: 0 | I35: 1 | J35: 0 | K35: 16 | L35: 10 | M35: 5 | N35: SUCCEEDED | O35: 145.188 | P35: 205.20788 | Q35: 143.16229 | R35: 159.43321 | S35: =IF(N35="SUCCEEDED",P35/Q35,"") | T35: =IF(N35="SUCCEEDED",P35/R35,"") | U35: =IF(N35="SUCCEEDED",IF(D35="B0",O35-P35,O35-Q35),"") | V35: 606.02018 | W35: 0 | X35: 0 | Y35: 16 | Z35: 0 | AA35: 0 | AB35: 0 | AC35: 8639 | AD35: 14287 | AE35: 13534 | AF35: 0.21513625 | AG35: 0.0054219938 | AH35: 0.000425 | AI35: =AF35+AG35+AH35 | AJ35: 0
A36: 1 | B36: 18 | C36: med3_11 | D36: A1 | E36: 1st | F36: med3 | G36: medium | H36: 0 | I36: 1 | J36: 0 | K36: 11 | L36: 6 | M36: 2 | N36: SUCCEEDED | O36: 206.717 | P36: 315.156 | Q36: 205.46621 | R36: 205.46621 | S36: =IF(N36="SUCCEEDED",P36/Q36,"") | T36: =IF(N36="SUCCEEDED",P36/R36,"") | U36: =IF(N36="SUCCEEDED",IF(D36="B0",O36-P36,O36-Q36),"") | V36: 667.03841 | W36: 0 | X36: 0 | Y36: 11 | Z36: 0 | AA36: 0 | AB36: 0 | AC36: 6305 | AD36: 22585 | AE36: 22084 | AF36: 0.32722375 | AG36: 0.0065583794 | AH36: 0.0003 | AI36: =AF36+AG36+AH36 | AJ36: 0
A37: 1 | B37: 18 | C37: med3_11 | D37: B0 | E37: 2nd | F37: med3 | G37: medium | H37: 0 | I37: 1 | J37: 0 | K37: 11 | L37: 6 | M37: 2 | N37: SUCCEEDED | O37: 285.665 | P37: 281.78597 | Q37: 201.49111 | R37: 211.22576 | S37: =IF(N37="SUCCEEDED",P37/Q37,"") | T37: =IF(N37="SUCCEEDED",P37/R37,"") | U37: =IF(N37="SUCCEEDED",IF(D37="B0",O37-P37,O37-Q37),"") | V37: 0.70335841 | W37: 1 | X37: 0.5382 | Y37: 11 | Z37: 0 | AA37: 0 | AB37: 0 | AC37: 6306 | AD37: 20425 | AE37: 19942 | AF37: 0.2969855 | AG37: 0.0018964961 | AH37: 0.000275 | AI37: =AF37+AG37+AH37 | AJ37: 0
A38: 1 | B38: 19 | C38: med2_45 | D38: B0 | E38: 1st | F38: med2 | G38: medium | H38: 0 | I38: 0 | J38: 0 | K38: 9 | L38: 4 | M38: 5 | N38: SUCCEEDED | O38: 187.303 | P38: 185.0054 | Q38: 125.45583 | R38: 131.82038 | S38: =IF(N38="SUCCEEDED",P38/Q38,"") | T38: =IF(N38="SUCCEEDED",P38/R38,"") | U38: =IF(N38="SUCCEEDED",IF(D38="B0",O38-P38,O38-Q38),"") | V38: 0.43501401 | W38: 0 | X38: 0 | Y38: 9 | Z38: 0 | AA38: 0 | AB38: 0 | AC38: 3900 | AD38: 12797 | AE38: 12413 | AF38: 0.185983 | AG38: 0.0012442929 | AH38: 0.000225 | AI38: =AF38+AG38+AH38 | AJ38: 0
A39: 1 | B39: 19 | C39: med2_45 | D39: A1 | E39: 2nd | F39: med2 | G39: medium | H39: 0 | I39: 0 | J39: 0 | K39: 9 | L39: 4 | M39: 5 | N39: SUCCEEDED | O39: 145.361 | P39: 228.78467 | Q39: 144.48537 | R39: 161.64562 | S39: =IF(N39="SUCCEEDED",P39/Q39,"") | T39: =IF(N39="SUCCEEDED",P39/R39,"") | U39: =IF(N39="SUCCEEDED",IF(D39="B0",O39-P39,O39-Q39),"") | V39: 185.88715 | W39: 0 | X39: 0 | Y39: 9 | Z39: 0 | AA39: 0 | AB39: 0 | AC39: 3888 | AD39: 16465 | AE39: 16084 | AF39: 0.237314 | AG39: 0.0027722139 | AH39: 0.00025 | AI39: =AF39+AG39+AH39 | AJ39: 0
A40: 1 | B40: 20 | C40: easy1_14 | D40: A1 | E40: 1st | F40: easy1 | G40: easy | H40: 1 | I40: 0 | J40: 0 | K40: 5 | L40: 4 | M40: 2 | N40: SUCCEEDED | O40: 66.034 | P40: 86.935781 | Q40: 65.53678 | R40: 78.405062 | S40: =IF(N40="SUCCEEDED",P40/Q40,"") | T40: =IF(N40="SUCCEEDED",P40/R40,"") | U40: =IF(N40="SUCCEEDED",IF(D40="B0",O40-P40,O40-Q40),"") | V40: 82.991601 | W40: 0 | X40: 0 | Y40: 5 | Z40: 0 | AA40: 0 | AB40: 0 | AC40: 2152 | AD40: 5408 | AE40: 5179 | AF40: 0.079478 | AG40: 0.0011374723 | AH40: 0.00015 | AI40: =AF40+AG40+AH40 | AJ40: 0
...

Sheet Paired
A1: Batch | B1: Pos | C1: Task | D1: Template | E1: First arm | F1: Status B0 | G1: Status A1 | H1: Both succeeded | I1: T_exec B0 (s) | J1: T_exec A1 (s) | K1: Speedup B0/A1 | L1: ln speedup | M1: Latency reduction | N1: Cold-adjusted speedup | O1: T_dec (s) | P1: DAG exact | Q1: Speedup incl. T_dec | R1: ln speedup incl. T_dec | S1: C_Total B0 ($) | T1: C_Total A1 ($) | U1: C_Total A1/B0 | V1: Correct B0 | W1: Correct A1 | X1: Arms disagree
A2: 1 | B2: 1 | C2: easy1_49 | D2: easy1 | E2: B0 | F2: SUCCEEDED | G2: SUCCEEDED | H2: =IF(AND(F2="SUCCEEDED",G2="SUCCEEDED"),1,0) | I2: =SUMIFS('Arm results'!$O$2:$O$201,'Arm results'!$C$2:$C$201,$C2,'Arm results'!$D$2:$D$201,"B0") | J2: =SUMIFS('Arm results'!$O$2:$O$201,'Arm results'!$C$2:$C$201,$C2,'Arm results'!$D$2:$D$201,"A1") | K2: =IF(H2=1,I2/J2,"") | L2: =IF(H2=1,LN(K2),"") | M2: =IF(H2=1,(I2-J2)/I2,"") | N2: =IF(H2=1,(I2-SUMIFS('Arm results'!$X$2:$X$201,'Arm results'!$C$2:$C$201,$C2,'Arm results'!$D$2:$D$201,"B0"))/(J2-SUMIFS('Arm results'!$X$2:$X$201,'Arm results'!$C$2:$C$201,$C2,'Arm results'!$D$2:$D$201,"A1")),"") | O2: 1.4768133 | P2: 1 | Q2: =IF(H2=1,(I2+O2)/(J2+O2),"") | R2: =IF(H2=1,LN(Q2),"") | S2: =SUMIFS('Arm results'!$AI$2:$AI$201,'Arm results'!$C$2:$C$201,$C2,'Arm results'!$D$2:$D$201,"B0") | T2: =SUMIFS('Arm results'!$AI$2:$AI$201,'Arm results'!$C$2:$C$201,$C2,'Arm results'!$D$2:$D$201,"A1") | U2: =IF(H2=1,T2/S2,"") | V2: =SUMIFS('Arm results'!$AJ$2:$AJ$201,'Arm results'!$C$2:$C$201,$C2,'Arm results'!$D$2:$D$201,"B0") | W2: =SUMIFS('Arm results'!$AJ$2:$AJ$201,'Arm results'!$C$2:$C$201,$C2,'Arm results'!$D$2:$D$201,"A1") | X2: =IF(V2<>W2,1,0)
A3: 1 | B3: 2 | C3: med1_37 | D3: med1 | E3: A1 | F3: SUCCEEDED | G3: SUCCEEDED | H3: =IF(AND(F3="SUCCEEDED",G3="SUCCEEDED"),1,0) | I3: =SUMIFS('Arm results'!$O$2:$O$201,'Arm results'!$C$2:$C$201,$C3,'Arm results'!$D$2:$D$201,"B0") | J3: =SUMIFS('Arm results'!$O$2:$O$201,'Arm results'!$C$2:$C$201,$C3,'Arm results'!$D$2:$D$201,"A1") | K3: =IF(H3=1,I3/J3,"") | L3: =IF(H3=1,LN(K3),"") | M3: =IF(H3=1,(I3-J3)/I3,"") | N3: =IF(H3=1,(I3-SUMIFS('Arm results'!$X$2:$X$201,'Arm results'!$C$2:$C$201,$C3,'Arm results'!$D$2:$D$201,"B0"))/(J3-SUMIFS('Arm results'!$X$2:$X$201,'Arm results'!$C$2:$C$201,$C3,'Arm results'!$D$2:$D$201,"A1")),"") | O3: 2.1985248 | P3: 1 | Q3: =IF(H3=1,(I3+O3)/(J3+O3),"") | R3: =IF(H3=1,LN(Q3),"") | S3: =SUMIFS('Arm results'!$AI$2:$AI$201,'Arm results'!$C$2:$C$201,$C3,'Arm results'!$D$2:$D$201,"B0") | T3: =SUMIFS('Arm results'!$AI$2:$AI$201,'Arm results'!$C$2:$C$201,$C3,'Arm results'!$D$2:$D$201,"A1") | U3: =IF(H3=1,T3/S3,"") | V3: =SUMIFS('Arm results'!$AJ$2:$AJ$201,'Arm results'!$C$2:$C$201,$C3,'Arm results'!$D$2:$D$201,"B0") | W3: =SUMIFS('Arm results'!$AJ$2:$AJ$201,'Arm results'!$C$2:$C$201,$C3,'Arm results'!$D$2:$D$201,"A1") | X3: =IF(V3<>W3,1,0)
A4: 1 | B4: 3 | C4: easy1_12 | D4: easy1 | E4: B0 | F4: SUCCEEDED | G4: SUCCEEDED | H4: =IF(AND(F4="SUCCEEDED",G4="SUCCEEDED"),1,0) | I4: =SUMIFS('Arm results'!$O$2:$O$201,'Arm results'!$C$2:$C$201,$C4,'Arm results'!$D$2:$D$201,"B0") | J4: =SUMIFS('Arm results'!$O$2:$O$201,'Arm results'!$C$2:$C$201,$C4,'Arm results'!$D$2:$D$201,"A1") | K4: =IF(H4=1,I4/J4,"") | L4: =IF(H4=1,LN(K4),"") | M4: =IF(H4=1,(I4-J4)/I4,"") | N4: =IF(H4=1,(I4-SUMIFS('Arm results'!$X$2:$X$201,'Arm results'!$C$2:$C$201,$C4,'Arm results'!$D$2:$D$201,"B0"))/(J4-SUMIFS('Arm results'!$X$2:$X$201,'Arm results'!$C$2:$C$201,$C4,'Arm results'!$D$2:$D$201,"A1")),"") | O4: 2.0976259 | P4: 1 | Q4: =IF(H4=1,(I4+O4)/(J4+O4),"") | R4: =IF(H4=1,LN(Q4),"") | S4: =SUMIFS('Arm results'!$AI$2:$AI$201,'Arm results'!$C$2:$C$201,$C4,'Arm results'!$D$2:$D$201,"B0") | T4: =SUMIFS('Arm results'!$AI$2:$AI$201,'Arm results'!$C$2:$C$201,$C4,'Arm results'!$D$2:$D$201,"A1") | U4: =IF(H4=1,T4/S4,"") | V4: =SUMIFS('Arm results'!$AJ$2:$AJ$201,'Arm results'!$C$2:$C$201,$C4,'Arm results'!$D$2:$D$201,"B0") | W4: =SUMIFS('Arm results'!$AJ$2:$AJ$201,'Arm results'!$C$2:$C$201,$C4,'Arm results'!$D$2:$D$201,"A1") | X4: =IF(V4<>W4,1,0)
A5: 1 | B5: 4 | C5: easy2_26 | D5: easy2 | E5: A1 | F5: SUCCEEDED | G5: SUCCEEDED | H5: =IF(AND(F5="SUCCEEDED",G5="SUCCEEDED"),1,0) | I5: =SUMIFS('Arm results'!$O$2:$O$201,'Arm results'!$C$2:$C$201,$C5,'Arm results'!$D$2:$D$201,"B0") | J5: =SUMIFS('Arm results'!$O$2:$O$201,'Arm results'!$C$2:$C$201,$C5,'Arm results'!$D$2:$D$201,"A1") | K5: =IF(H5=1,I5/J5,"") | L5: =IF(H5=1,LN(K5),"") | M5: =IF(H5=1,(I5-J5)/I5,"") | N5: =IF(H5=1,(I5-SUMIFS('Arm results'!$X$2:$X$201,'Arm results'!$C$2:$C$201,$C5,'Arm results'!$D$2:$D$201,"B0"))/(J5-SUMIFS('Arm results'!$X$2:$X$201,'Arm results'!$C$2:$C$201,$C5,'Arm results'!$D$2:$D$201,"A1")),"") | O5: 2.3765719 | P5: 1 | Q5: =IF(H5=1,(I5+O5)/(J5+O5),"") | R5: =IF(H5=1,LN(Q5),"") | S5: =SUMIFS('Arm results'!$AI$2:$AI$201,'Arm results'!$C$2:$C$201,$C5,'Arm results'!$D$2:$D$201,"B0") | T5: =SUMIFS('Arm results'!$AI$2:$AI$201,'Arm results'!$C$2:$C$201,$C5,'Arm results'!$D$2:$D$201,"A1") | U5: =IF(H5=1,T5/S5,"") | V5: =SUMIFS('Arm results'!$AJ$2:$AJ$201,'Arm results'!$C$2:$C$201,$C5,'Arm results'!$D$2:$D$201,"B0") | W5: =SUMIFS('Arm results'!$AJ$2:$AJ$201,'Arm results'!$C$2:$C$201,$C5,'Arm results'!$D$2:$D$201,"A1") | X5: =IF(V5<>W5,1,0)
A6: 1 | B6: 5 | C6: hard1_11 | D6: hard1 | E6: B0 | F6: SUCCEEDED | G6: SUCCEEDED | H6: =IF(AND(F6="SUCCEEDED",G6="SUCCEEDED"),1,0) | I6: =SUMIFS('Arm results'!$O$2:$O$201,'Arm results'!$C$2:$C$201,$C6,'Arm results'!$D$2:$D$201,"B0") | J6: =SUMIFS('Arm results'!$O$2:$O$201,'Arm results'!$C$2:$C$201,$C6,'Arm results'!$D$2:$D$201,"A1") | K6: =IF(H6=1,I6/J6,"") | L6: =IF(H6=1,LN(K6),"") | M6: =IF(H6=1,(I6-J6)/I6,"") | N6: =IF(H6=1,(I6-SUMIFS('Arm results'!$X$2:$X$201,'Arm results'!$C$2:$C$201,$C6,'Arm results'!$D$2:$D$201,"B0"))/(J6-SUMIFS('Arm results'!$X$2:$X$201,'Arm results'!$C$2:$C$201,$C6,'Arm results'!$D$2:$D$201,"A1")),"") | O6: 3.1215492 | P6: 1 | Q6: =IF(H6=1,(I6+O6)/(J6+O6),"") | R6: =IF(H6=1,LN(Q6),"") | S6: =SUMIFS('Arm results'!$AI$2:$AI$201,'Arm results'!$C$2:$C$201,$C6,'Arm results'!$D$2:$D$201,"B0") | T6: =SUMIFS('Arm results'!$AI$2:$AI$201,'Arm results'!$C$2:$C$201,$C6,'Arm results'!$D$2:$D$201,"A1") | U6: =IF(H6=1,T6/S6,"") | V6: =SUMIFS('Arm results'!$AJ$2:$AJ$201,'Arm results'!$C$2:$C$201,$C6,'Arm results'!$D$2:$D$201,"B0") | W6: =SUMIFS('Arm results'!$AJ$2:$AJ$201,'Arm results'!$C$2:$C$201,$C6,'Arm results'!$D$2:$D$201,"A1") | X6: =IF(V6<>W6,1,0)
A7: 1 | B7: 6 | C7: easy1_11 | D7: easy1 | E7: A1 | F7: SUCCEEDED | G7: SUCCEEDED | H7: =IF(AND(F7="SUCCEEDED",G7="SUCCEEDED"),1,0) | I7: =SUMIFS('Arm results'!$O$2:$O$201,'Arm results'!$C$2:$C$201,$C7,'Arm results'!$D$2:$D$201,"B0") | J7: =SUMIFS('Arm results'!$O$2:$O$201,'Arm results'!$C$2:$C$201,$C7,'Arm results'!$D$2:$D$201,"A1") | K7: =IF(H7=1,I7/J7,"") | L7: =IF(H7=1,LN(K7),"") | M7: =IF(H7=1,(I7-J7)/I7,"") | N7: =IF(H7=1,(I7-SUMIFS('Arm results'!$X$2:$X$201,'Arm results'!$C$2:$C$201,$C7,'Arm results'!$D$2:$D$201,"B0"))/(J7-SUMIFS('Arm results'!$X$2:$X$201,'Arm results'!$C$2:$C$201,$C7,'Arm results'!$D$2:$D$201,"A1")),"") | O7: 2.2928154 | P7: 1 | Q7: =IF(H7=1,(I7+O7)/(J7+O7),"") | R7: =IF(H7=1,LN(Q7),"") | S7: =SUMIFS('Arm results'!$AI$2:$AI$201,'Arm results'!$C$2:$C$201,$C7,'Arm results'!$D$2:$D$201,"B0") | T7: =SUMIFS('Arm results'!$AI$2:$AI$201,'Arm results'!$C$2:$C$201,$C7,'Arm results'!$D$2:$D$201,"A1") | U7: =IF(H7=1,T7/S7,"") | V7: =SUMIFS('Arm results'!$AJ$2:$AJ$201,'Arm results'!$C$2:$C$201,$C7,'Arm results'!$D$2:$D$201,"B0") | W7: =SUMIFS('Arm results'!$AJ$2:$AJ$201,'Arm results'!$C$2:$C$201,$C7,'Arm results'!$D$2:$D$201,"A1") | X7: =IF(V7<>W7,1,0)
A8: 1 | B8: 7 | C8: easy1_3 | D8: easy1 | E8: B0 | F8: SUCCEEDED | G8: SUCCEEDED | H8: =IF(AND(F8="SUCCEEDED",G8="SUCCEEDED"),1,0) | I8: =SUMIFS('Arm results'!$O$2:$O$201,'Arm results'!$C$2:$C$201,$C8,'Arm results'!$D$2:$D$201,"B0") | J8: =SUMIFS('Arm results'!$O$2:$O$201,'Arm results'!$C$2:$C$201,$C8,'Arm results'!$D$2:$D$201,"A1") | K8: =IF(H8=1,I8/J8,"") | L8: =IF(H8=1,LN(K8),"") | M8: =IF(H8=1,(I8-J8)/I8,"") | N8: =IF(H8=1,(I8-SUMIFS('Arm results'!$X$2:$X$201,'Arm results'!$C$2:$C$201,$C8,'Arm results'!$D$2:$D$201,"B0"))/(J8-SUMIFS('Arm results'!$X$2:$X$201,'Arm results'!$C$2:$C$201,$C8,'Arm results'!$D$2:$D$201,"A1")),"") | O8: 2.2630755 | P8: 1 | Q8: =IF(H8=1,(I8+O8)/(J8+O8),"") | R8: =IF(H8=1,LN(Q8),"") | S8: =SUMIFS('Arm results'!$AI$2:$AI$201,'Arm results'!$C$2:$C$201,$C8,'Arm results'!$D$2:$D$201,"B0") | T8: =SUMIFS('Arm results'!$AI$2:$AI$201,'Arm results'!$C$2:$C$201,$C8,'Arm results'!$D$2:$D$201,"A1") | U8: =IF(H8=1,T8/S8,"") | V8: =SUMIFS('Arm results'!$AJ$2:$AJ$201,'Arm results'!$C$2:$C$201,$C8,'Arm results'!$D$2:$D$201,"B0") | W8: =SUMIFS('Arm results'!$AJ$2:$AJ$201,'Arm results'!$C$2:$C$201,$C8,'Arm results'!$D$2:$D$201,"A1") | X8: =IF(V8<>W8,1,0)
A9: 1 | B9: 8 | C9: easy2_18 | D9: easy2 | E9: A1 | F9: SUCCEEDED | G9: SUCCEEDED | H9: =IF(AND(F9="SUCCEEDED",G9="SUCCEEDED"),1,0) | I9: =SUMIFS('Arm results'!$O$2:$O$201,'Arm results'!$C$2:$C$201,$C9,'Arm results'!$D$2:$D$201,"B0") | J9: =SUMIFS('Arm results'!$O$2:$O$201,'Arm results'!$C$2:$C$201,$C9,'Arm results'!$D$2:$D$201,"A1") | K9: =IF(H9=1,I9/J9,"") | L9: =IF(H9=1,LN(K9),"") | M9: =IF(H9=1,(I9-J9)/I9,"") | N9: =IF(H9=1,(I9-SUMIFS('Arm results'!$X$2:$X$201,'Arm results'!$C$2:$C$201,$C9,'Arm results'!$D$2:$D$201,"B0"))/(J9-SUMIFS('Arm results'!$X$2:$X$201,'Arm results'!$C$2:$C$201,$C9,'Arm results'!$D$2:$D$201,"A1")),"") | O9: 1.2275173 | P9: 0 | Q9: =IF(H9=1,(I9+O9)/(J9+O9),"") | R9: =IF(H9=1,LN(Q9),"") | S9: =SUMIFS('Arm results'!$AI$2:$AI$201,'Arm results'!$C$2:$C$201,$C9,'Arm results'!$D$2:$D$201,"B0") | T9: =SUMIFS('Arm results'!$AI$2:$AI$201,'Arm results'!$C$2:$C$201,$C9,'Arm results'!$D$2:$D$201,"A1") | U9: =IF(H9=1,T9/S9,"") | V9: =SUMIFS('Arm results'!$AJ$2:$AJ$201,'Arm results'!$C$2:$C$201,$C9,'Arm results'!$D$2:$D$201,"B0") | W9: =SUMIFS('Arm results'!$AJ$2:$AJ$201,'Arm results'!$C$2:$C$201,$C9,'Arm results'!$D$2:$D$201,"A1") | X9: =IF(V9<>W9,1,0)
A10: 1 | B10: 9 | C10: easy2_25 | D10: easy2 | E10: B0 | F10: SUCCEEDED | G10: SUCCEEDED | H10: =IF(AND(F10="SUCCEEDED",G10="SUCCEEDED"),1,0) | I10: =SUMIFS('Arm results'!$O$2:$O$201,'Arm results'!$C$2:$C$201,$C10,'Arm results'!$D$2:$D$201,"B0") | J10: =SUMIFS('Arm results'!$O$2:$O$201,'Arm results'!$C$2:$C$201,$C10,'Arm results'!$D$2:$D$201,"A1") | K10: =IF(H10=1,I10/J10,"") | L10: =IF(H10=1,LN(K10),"") | M10: =IF(H10=1,(I10-J10)/I10,"") | N10: =IF(H10=1,(I10-SUMIFS('Arm results'!$X$2:$X$201,'Arm results'!$C$2:$C$201,$C10,'Arm results'!$D$2:$D$201,"B0"))/(J10-SUMIFS('Arm results'!$X$2:$X$201,'Arm results'!$C$2:$C$201,$C10,'Arm results'!$D$2:$D$201,"A1")),"") | O10: 1.3853091 | P10: 0 | Q10: =IF(H10=1,(I10+O10)/(J10+O10),"") | R10: =IF(H10=1,LN(Q10),"") | S10: =SUMIFS('Arm results'!$AI$2:$AI$201,'Arm results'!$C$2:$C$201,$C10,'Arm results'!$D$2:$D$201,"B0") | T10: =SUMIFS('Arm results'!$AI$2:$AI$201,'Arm results'!$C$2:$C$201,$C10,'Arm results'!$D$2:$D$201,"A1") | U10: =IF(H10=1,T10/S10,"") | V10: =SUMIFS('Arm results'!$AJ$2:$AJ$201,'Arm results'!$C$2:$C$201,$C10,'Arm results'!$D$2:$D$201,"B0") | W10: =SUMIFS('Arm results'!$AJ$2:$AJ$201,'Arm results'!$C$2:$C$201,$C10,'Arm results'!$D$2:$D$201,"A1") | X10: =IF(V10<>W10,1,0)
A11: 1 | B11: 10 | C11: protein_1CAD_query_2_mask_4 | D11: hard4 | E11: A1 | F11: SUCCEEDED | G11: SUCCEEDED | H11: =IF(AND(F11="SUCCEEDED",G11="SUCCEEDED"),1,0) | I11: =SUMIFS('Arm results'!$O$2:$O$201,'Arm results'!$C$2:$C$201,$C11,'Arm results'!$D$2:$D$201,"B0") | J11: =SUMIFS('Arm results'!$O$2:$O$201,'Arm results'!$C$2:$C$201,$C11,'Arm results'!$D$2:$D$201,"A1") | K11: =IF(H11=1,I11/J11,"") | L11: =IF(H11=1,LN(K11),"") | M11: =IF(H11=1,(I11-J11)/I11,"") | N11: =IF(H11=1,(I11-SUMIFS('Arm results'!$X$2:$X$201,'Arm results'!$C$2:$C$201,$C11,'Arm results'!$D$2:$D$201,"B0"))/(J11-SUMIFS('Arm results'!$X$2:$X$201,'Arm results'!$C$2:$C$201,$C11,'Arm results'!$D$2:$D$201,"A1")),"") | O11: 2.3565429 | P11: 0 | Q11: =IF(H11=1,(I11+O11)/(J11+O11),"") | R11: =IF(H11=1,LN(Q11),"") | S11: =SUMIFS('Arm results'!$AI$2:$AI$201,'Arm results'!$C$2:$C$201,$C11,'Arm results'!$D$2:$D$201,"B0") | T11: =SUMIFS('Arm results'!$AI$2:$AI$201,'Arm results'!$C$2:$C$201,$C11,'Arm results'!$D$2:$D$201,"A1") | U11: =IF(H11=1,T11/S11,"") | V11: =SUMIFS('Arm results'!$AJ$2:$AJ$201,'Arm results'!$C$2:$C$201,$C11,'Arm results'!$D$2:$D$201,"B0") | W11: =SUMIFS('Arm results'!$AJ$2:$AJ$201,'Arm results'!$C$2:$C$201,$C11,'Arm results'!$D$2:$D$201,"A1") | X11: =IF(V11<>W11,1,0)
A12: 1 | B12: 11 | C12: med2_22 | D12: med2 | E12: B0 | F12: SUCCEEDED | G12: SUCCEEDED | H12: =IF(AND(F12="SUCCEEDED",G12="SUCCEEDED"),1,0) | I12: =SUMIFS('Arm results'!$O$2:$O$201,'Arm results'!$C$2:$C$201,$C12,'Arm results'!$D$2:$D$201,"B0") | J12: =SUMIFS('Arm results'!$O$2:$O$201,'Arm results'!$C$2:$C$201,$C12,'Arm results'!$D$2:$D$201,"A1") | K12: =IF(H12=1,I12/J12,"") | L12: =IF(H12=1,LN(K12),"") | M12: =IF(H12=1,(I12-J12)/I12,"") | N12: =IF(H12=1,(I12-SUMIFS('Arm results'!$X$2:$X$201,'Arm results'!$C$2:$C$201,$C12,'Arm results'!$D$2:$D$201,"B0"))/(J12-SUMIFS('Arm results'!$X$2:$X$201,'Arm results'!$C$2:$C$201,$C12,'Arm results'!$D$2:$D$201,"A1")),"") | O12: 1.9883363 | P12: 1 | Q12: =IF(H12=1,(I12+O12)/(J12+O12),"") | R12: =IF(H12=1,LN(Q12),"") | S12: =SUMIFS('Arm results'!$AI$2:$AI$201,'Arm results'!$C$2:$C$201,$C12,'Arm results'!$D$2:$D$201,"B0") | T12: =SUMIFS('Arm results'!$AI$2:$AI$201,'Arm results'!$C$2:$C$201,$C12,'Arm results'!$D$2:$D$201,"A1") | U12: =IF(H12=1,T12/S12,"") | V12: =SUMIFS('Arm results'!$AJ$2:$AJ$201,'Arm results'!$C$2:$C$201,$C12,'Arm results'!$D$2:$D$201,"B0") | W12: =SUMIFS('Arm results'!$AJ$2:$AJ$201,'Arm results'!$C$2:$C$201,$C12,'Arm results'!$D$2:$D$201,"A1") | X12: =IF(V12<>W12,1,0)
A13: 1 | B13: 12 | C13: protein_1CRN_query_3_mask_4 | D13: hard4 | E13: A1 | F13: SUCCEEDED | G13: SUCCEEDED | H13: =IF(AND(F13="SUCCEEDED",G13="SUCCEEDED"),1,0) | I13: =SUMIFS('Arm results'!$O$2:$O$201,'Arm results'!$C$2:$C$201,$C13,'Arm results'!$D$2:$D$201,"B0") | J13: =SUMIFS('Arm results'!$O$2:$O$201,'Arm results'!$C$2:$C$201,$C13,'Arm results'!$D$2:$D$201,"A1") | K13: =IF(H13=1,I13/J13,"") | L13: =IF(H13=1,LN(K13),"") | M13: =IF(H13=1,(I13-J13)/I13,"") | N13: =IF(H13=1,(I13-SUMIFS('Arm results'!$X$2:$X$201,'Arm results'!$C$2:$C$201,$C13,'Arm results'!$D$2:$D$201,"B0"))/(J13-SUMIFS('Arm results'!$X$2:$X$201,'Arm results'!$C$2:$C$201,$C13,'Arm results'!$D$2:$D$201,"A1")),"") | O13: 2.6193399 | P13: 0 | Q13: =IF(H13=1,(I13+O13)/(J13+O13),"") | R13: =IF(H13=1,LN(Q13),"") | S13: =SUMIFS('Arm results'!$AI$2:$AI$201,'Arm results'!$C$2:$C$201,$C13,'Arm results'!$D$2:$D$201,"B0") | T13: =SUMIFS('Arm results'!$AI$2:$AI$201,'Arm results'!$C$2:$C$201,$C13,'Arm results'!$D$2:$D$201,"A1") | U13: =IF(H13=1,T13/S13,"") | V13: =SUMIFS('Arm results'!$AJ$2:$AJ$201,'Arm results'!$C$2:$C$201,$C13,'Arm results'!$D$2:$D$201,"B0") | W13: =SUMIFS('Arm results'!$AJ$2:$AJ$201,'Arm results'!$C$2:$C$201,$C13,'Arm results'!$D$2:$D$201,"A1") | X13: =IF(V13<>W13,1,0)
... A101: 2 | B101: 50 | C101: med1_15 | D101: med1 | E101: A1 | F101: SUCCEEDED | G101: SUCCEEDED | H101: =IF(AND(F101="SUCCEEDED",G101="SUCCEEDED"),1,0) | I101: =SUMIFS('Arm results'!$O$2:$O$201,'Arm results'!$C$2:$C$201,$C101,'Arm results'!$D$2:$D$201,"B0") | J101: =SUMIFS('Arm results'!$O$2:$O$201,'Arm results'!$C$2:$C$201,$C101,'Arm results'!$D$2:$D$201,"A1") | K101: =IF(H101=1,I101/J101,"") | L101: =IF(H101=1,LN(K101),"") | M101: =IF(H101=1,(I101-J101)/I101,"") | N101: =IF(H101=1,(I101-SUMIFS('Arm results'!$X$2:$X$201,'Arm results'!$C$2:$C$201,$C101,'Arm results'!$D$2:$D$201,"B0"))/(J101-SUMIFS('Arm results'!$X$2:$X$201,'Arm results'!$C$2:$C$201,$C101,'Arm results'!$D$2:$D$201,"A1")),"") | O101: 2.6585031 | P101: 1 | Q101: =IF(H101=1,(I101+O101)/(J101+O101),"") | R101: =IF(H101=1,LN(Q101),"") | S101: =SUMIFS('Arm results'!$AI$2:$AI$201,'Arm results'!$C$2:$C$201,$C101,'Arm results'!$D$2:$D$201,"B0") | T101: =SUMIFS('Arm results'!$AI$2:$AI$201,'Arm results'!$C$2:$C$201,$C101,'Arm results'!$D$2:$D$201,"A1") | U101: =IF(H101=1,T101/S101,"") | V101: =SUMIFS('Arm results'!$AJ$2:$AJ$201,'Arm results'!$C$2:$C$201,$C101,'Arm results'!$D$2:$D$201,"B0") | W101: =SUMIFS('Arm results'!$AJ$2:$AJ$201,'Arm results'!$C$2:$C$201,$C101,'Arm results'!$D$2:$D$201,"A1") | X101: =IF(V101<>W101,1,0)
C102: Totals | H102: =SUM(H2:H101) | P102: =SUM(P2:P101) | S102: =SUM(S2:S101) | T102: =SUM(T2:T101) | V102: =SUM(V2:V101) | W102: =SUM(W2:W101) | X102: =SUM(X2:X101)
C104: Values are formulas over 'Arm results' except Status, T_dec and DAG exact (blue: statuses from the run records, T_dec and exact-DAG flag from decompose/dec-1/rows.jsonl). Speedup columns are blank unless both arms succeeded (prereg §8).

Sheet Templates
A1: Template | B1: Tasks | C1: Both arms succeeded | D1: Completed B0 | E1: Completed A1 | F1: N | G1: D | H1: W | I1: N/D | J1: Mean ln speedup | K1: S (geo-mean speedup) | L1: S (script) | M1: Replay B0 (script) | N1: Replay A1 (script) | O1: Mean ln incl. T_dec | P1: S incl. T_dec | Q1: C_Total A1/B0 (script) | R1: Mean T_exec B0 (s) | S1: Mean T_exec A1 (s) | T1: Correct B0 | U1: Correct A1 | V1: Accuracy B0 | W1: Accuracy A1 | X1: Exposed tasks | Y1: Flagged tasks
A2: easy1 | B2: =COUNTIF(Paired!$D$2:$D$101,$A2) | C2: =SUMIFS(Paired!$H$2:$H$101,Paired!$D$2:$D$101,$A2) | D2: =COUNTIFS('Arm results'!$F$2:$F$201,$A2,'Arm results'!$D$2:$D$201,"B0",'Arm results'!$N$2:$N$201,"SUCCEEDED") | E2: =COUNTIFS('Arm results'!$F$2:$F$201,$A2,'Arm results'!$D$2:$D$201,"A1",'Arm results'!$N$2:$N$201,"SUCCEEDED") | F2: 5 | G2: 4 | H2: 2 | I2: =F2/G2 | J2: =AVERAGEIFS(Paired!$L$2:$L$101,Paired!$D$2:$D$101,$A2,Paired!$H$2:$H$101,1) | K2: =EXP(J2) | L2: 1.2893829 | M2: 1.37503 | N2: 1.3381298 | O2: =AVERAGEIFS(Paired!$R$2:$R$101,Paired!$D$2:$D$101,$A2,Paired!$H$2:$H$101,1) | P2: =EXP(O2) | Q2: 1.045307 | R2: =AVERAGEIFS('Arm results'!$O$2:$O$201,'Arm results'!$F$2:$F$201,$A2,'Arm results'!$D$2:$D$201,"B0",'Arm results'!$N$2:$N$201,"SUCCEEDED") | S2: =AVERAGEIFS('Arm results'!$O$2:$O$201,'Arm results'!$F$2:$F$201,$A2,'Arm results'!$D$2:$D$201,"A1",'Arm results'!$N$2:$N$201,"SUCCEEDED") | T2: =SUMIFS('Arm results'!$AJ$2:$AJ$201,'Arm results'!$F$2:$F$201,$A2,'Arm results'!$D$2:$D$201,"B0") | U2: =SUMIFS('Arm results'!$AJ$2:$AJ$201,'Arm results'!$F$2:$F$201,$A2,'Arm results'!$D$2:$D$201,"A1") | V2: =T2/B2 | W2: =U2/B2 | X2: =SUMIFS('Arm results'!$H$2:$H$201,'Arm results'!$F$2:$F$201,$A2,'Arm results'!$D$2:$D$201,"B0") | Y2: =SUMIFS('Arm results'!$I$2:$I$201,'Arm results'!$F$2:$F$201,$A2,'Arm results'!$D$2:$D$201,"B0")
A3: easy2 | B3: =COUNTIF(Paired!$D$2:$D$101,$A3) | C3: =SUMIFS(Paired!$H$2:$H$101,Paired!$D$2:$D$101,$A3) | D3: =COUNTIFS('Arm results'!$F$2:$F$201,$A3,'Arm results'!$D$2:$D$201,"B0",'Arm results'!$N$2:$N$201,"SUCCEEDED") | E3: =COUNTIFS('Arm results'!$F$2:$F$201,$A3,'Arm results'!$D$2:$D$201,"A1",'Arm results'!$N$2:$N$201,"SUCCEEDED") | F3: 5 | G3: 4 | H3: 2 | I3: =F3/G3 | J3: =AVERAGEIFS(Paired!$L$2:$L$101,Paired!$D$2:$D$101,$A3,Paired!$H$2:$H$101,1) | K3: =EXP(J3) | L3: 1.0415421 | M3: 1.0746163 | N3: 1.0675149 | O3: =AVERAGEIFS(Paired!$R$2:$R$101,Paired!$D$2:$D$101,$A3,Paired!$H$2:$H$101,1) | P3: =EXP(O3) | Q3: 1.0405519 | R3: =AVERAGEIFS('Arm results'!$O$2:$O$201,'Arm results'!$F$2:$F$201,$A3,'Arm results'!$D$2:$D$201,"B0",'Arm results'!$N$2:$N$201,"SUCCEEDED") | S3: =AVERAGEIFS('Arm results'!$O$2:$O$201,'Arm results'!$F$2:$F$201,$A3,'Arm results'!$D$2:$D$201,"A1",'Arm results'!$N$2:$N$201,"SUCCEEDED") | T3: =SUMIFS('Arm results'!$AJ$2:$AJ$201,'Arm results'!$F$2:$F$201,$A3,'Arm results'!$D$2:$D$201,"B0") | U3: =SUMIFS('Arm results'!$AJ$2:$AJ$201,'Arm results'!$F$2:$F$201,$A3,'Arm results'!$D$2:$D$201,"A1") | V3: =T3/B3 | W3: =U3/B3 | X3: =SUMIFS('Arm results'!$H$2:$H$201,'Arm results'!$F$2:$F$201,$A3,'Arm results'!$D$2:$D$201,"B0") | Y3: =SUMIFS('Arm results'!$I$2:$I$201,'Arm results'!$F$2:$F$201,$A3,'Arm results'!$D$2:$D$201,"B0")
A4: hard1 | B4: =COUNTIF(Paired!$D$2:$D$101,$A4) | C4: =SUMIFS(Paired!$H$2:$H$101,Paired!$D$2:$D$101,$A4) | D4: =COUNTIFS('Arm results'!$F$2:$F$201,$A4,'Arm results'!$D$2:$D$201,"B0",'Arm results'!$N$2:$N$201,"SUCCEEDED") | E4: =COUNTIFS('Arm results'!$F$2:$F$201,$A4,'Arm results'!$D$2:$D$201,"A1",'Arm results'!$N$2:$N$201,"SUCCEEDED") | F4: 16 | G4: 9 | H4: 5 | I4: =F4/G4 | J4: =AVERAGEIFS(Paired!$L$2:$L$101,Paired!$D$2:$D$101,$A4,Paired!$H$2:$H$101,1) | K4: =EXP(J4) | L4: 1.3420808 | M4: 1.2630307 | N4: 1.2662592 | O4: =AVERAGEIFS(Paired!$R$2:$R$101,Paired!$D$2:$D$101,$A4,Paired!$H$2:$H$101,1) | P4: =EXP(O4) | Q4: 0.9851492 | R4: =AVERAGEIFS('Arm results'!$O$2:$O$201,'Arm results'!$F$2:$F$201,$A4,'Arm results'!$D$2:$D$201,"B0",'Arm results'!$N$2:$N$201,"SUCCEEDED") | S4: =AVERAGEIFS('Arm results'!$O$2:$O$201,'Arm results'!$F$2:$F$201,$A4,'Arm results'!$D$2:$D$201,"A1",'Arm results'!$N$2:$N$201,"SUCCEEDED") | T4: =SUMIFS('Arm results'!$AJ$2:$AJ$201,'Arm results'!$F$2:$F$201,$A4,'Arm results'!$D$2:$D$201,"B0") | U4: =SUMIFS('Arm results'!$AJ$2:$AJ$201,'Arm results'!$F$2:$F$201,$A4,'Arm results'!$D$2:$D$201,"A1") | V4: =T4/B4 | W4: =U4/B4 | X4: =SUMIFS('Arm results'!$H$2:$H$201,'Arm results'!$F$2:$F$201,$A4,'Arm results'!$D$2:$D$201,"B0") | Y4: =SUMIFS('Arm results'!$I$2:$I$201,'Arm results'!$F$2:$F$201,$A4,'Arm results'!$D$2:$D$201,"B0")
A5: hard2 | B5: =COUNTIF(Paired!$D$2:$D$101,$A5) | C5: =SUMIFS(Paired!$H$2:$H$101,Paired!$D$2:$D$101,$A5) | D5: =COUNTIFS('Arm results'!$F$2:$F$201,$A5,'Arm results'!$D$2:$D$201,"B0",'Arm results'!$N$2:$N$201,"SUCCEEDED") | E5: =COUNTIFS('Arm results'!$F$2:$F$201,$A5,'Arm results'!$D$2:$D$201,"A1",'Arm results'!$N$2:$N$201,"SUCCEEDED") | F5: 16 | G5: 10 | H5: 5 | I5: =F5/G5 | J5: =AVERAGEIFS(Paired!$L$2:$L$101,Paired!$D$2:$D$101,$A5,Paired!$H$2:$H$101,1) | K5: =EXP(J5) | L5: 1.0892335 | M5: 1.262398 | N5: 1.2555489 | O5: =AVERAGEIFS(Paired!$R$2:$R$101,Paired!$D$2:$D$101,$A5,Paired!$H$2:$H$101,1) | P5: =EXP(O5) | Q5: 1.1074881 | R5: =AVERAGEIFS('Arm results'!$O$2:$O$201,'Arm results'!$F$2:$F$201,$A5,'Arm results'!$D$2:$D$201,"B0",'Arm results'!$N$2:$N$201,"SUCCEEDED") | S5: =AVERAGEIFS('Arm results'!$O$2:$O$201,'Arm results'!$F$2:$F$201,$A5,'Arm results'!$D$2:$D$201,"A1",'Arm results'!$N$2:$N$201,"SUCCEEDED") | T5: =SUMIFS('Arm results'!$AJ$2:$AJ$201,'Arm results'!$F$2:$F$201,$A5,'Arm results'!$D$2:$D$201,"B0") | U5: =SUMIFS('Arm results'!$AJ$2:$AJ$201,'Arm results'!$F$2:$F$201,$A5,'Arm results'!$D$2:$D$201,"A1") | V5: =T5/B5 | W5: =U5/B5 | X5: =SUMIFS('Arm results'!$H$2:$H$201,'Arm results'!$F$2:$F$201,$A5,'Arm results'!$D$2:$D$201,"B0") | Y5: =SUMIFS('Arm results'!$I$2:$I$201,'Arm results'!$F$2:$F$201,$A5,'Arm results'!$D$2:$D$201,"B0")
A6: hard3 | B6: =COUNTIF(Paired!$D$2:$D$101,$A6) | C6: =SUMIFS(Paired!$H$2:$H$101,Paired!$D$2:$D$101,$A6) | D6: =COUNTIFS('Arm results'!$F$2:$F$201,$A6,'Arm results'!$D$2:$D$201,"B0",'Arm results'!$N$2:$N$201,"SUCCEEDED") | E6: =COUNTIFS('Arm results'!$F$2:$F$201,$A6,'Arm results'!$D$2:$D$201,"A1",'Arm results'!$N$2:$N$201,"SUCCEEDED") | F6: 15 | G6: 9 | H6: 4 | I6: =F6/G6 | J6: =AVERAGEIFS(Paired!$L$2:$L$101,Paired!$D$2:$D$101,$A6,Paired!$H$2:$H$101,1) | K6: =EXP(J6) | L6: 1.1973148 | M6: 1.4696986 | N6: 1.4075172 | O6: =AVERAGEIFS(Paired!$R$2:$R$101,Paired!$D$2:$D$101,$A6,Paired!$H$2:$H$101,1) | P6: =EXP(O6) | Q6: 1.2211052 | R6: =AVERAGEIFS('Arm results'!$O$2:$O$201,'Arm results'!$F$2:$F$201,$A6,'Arm results'!$D$2:$D$201,"B0",'Arm results'!$N$2:$N$201,"SUCCEEDED") | S6: =AVERAGEIFS('Arm results'!$O$2:$O$201,'Arm results'!$F$2:$F$201,$A6,'Arm results'!$D$2:$D$201,"A1",'Arm results'!$N$2:$N$201,"SUCCEEDED") | T6: =SUMIFS('Arm results'!$AJ$2:$AJ$201,'Arm results'!$F$2:$F$201,$A6,'Arm results'!$D$2:$D$201,"B0") | U6: =SUMIFS('Arm results'!$AJ$2:$AJ$201,'Arm results'!$F$2:$F$201,$A6,'Arm results'!$D$2:$D$201,"A1") | V6: =T6/B6 | W6: =U6/B6 | X6: =SUMIFS('Arm results'!$H$2:$H$201,'Arm results'!$F$2:$F$201,$A6,'Arm results'!$D$2:$D$201,"B0") | Y6: =SUMIFS('Arm results'!$I$2:$I$201,'Arm results'!$F$2:$F$201,$A6,'Arm results'!$D$2:$D$201,"B0")
A7: hard4 | B7: =COUNTIF(Paired!$D$2:$D$101,$A7) | C7: =SUMIFS(Paired!$H$2:$H$101,Paired!$D$2:$D$101,$A7) | D7: =COUNTIFS('Arm results'!$F$2:$F$201,$A7,'Arm results'!$D$2:$D$201,"B0",'Arm results'!$N$2:$N$201,"SUCCEEDED") | E7: =COUNTIFS('Arm results'!$F$2:$F$201,$A7,'Arm results'!$D$2:$D$201,"A1",'Arm results'!$N$2:$N$201,"SUCCEEDED") | F7: 6 | G7: 5 | H7: 2 | I7: =F7/G7 | J7: =AVERAGEIFS(Paired!$L$2:$L$101,Paired!$D$2:$D$101,$A7,Paired!$H$2:$H$101,1) | K7: =EXP(J7) | L7: 1.0531581 | M7: 1.0818308 | N7: 1.0879494 | O7: =AVERAGEIFS(Paired!$R$2:$R$101,Paired!$D$2:$D$101,$A7,Paired!$H$2:$H$101,1) | P7: =EXP(O7) | Q7: 1.0180723 | R7: =AVERAGEIFS('Arm results'!$O$2:$O$201,'Arm results'!$F$2:$F$201,$A7,'Arm results'!$D$2:$D$201,"B0",'Arm results'!$N$2:$N$201,"SUCCEEDED") | S7: =AVERAGEIFS('Arm results'!$O$2:$O$201,'Arm results'!$F$2:$F$201,$A7,'Arm results'!$D$2:$D$201,"A1",'Arm results'!$N$2:$N$201,"SUCCEEDED") | T7: =SUMIFS('Arm results'!$AJ$2:$AJ$201,'Arm results'!$F$2:$F$201,$A7,'Arm results'!$D$2:$D$201,"B0") | U7: =SUMIFS('Arm results'!$AJ$2:$AJ$201,'Arm results'!$F$2:$F$201,$A7,'Arm results'!$D$2:$D$201,"A1") | V7: =T7/B7 | W7: =U7/B7 | X7: =SUMIFS('Arm results'!$H$2:$H$201,'Arm results'!$F$2:$F$201,$A7,'Arm results'!$D$2:$D$201,"B0") | Y7: =SUMIFS('Arm results'!$I$2:$I$201,'Arm results'!$F$2:$F$201,$A7,'Arm results'!$D$2:$D$201,"B0")
A8: med1 | B8: =COUNTIF(Paired!$D$2:$D$101,$A8) | C8: =SUMIFS(Paired!$H$2:$H$101,Paired!$D$2:$D$101,$A8) | D8: =COUNTIFS('Arm results'!$F$2:$F$201,$A8,'Arm results'!$D$2:$D$201,"B0",'Arm results'!$N$2:$N$201,"SUCCEEDED") | E8: =COUNTIFS('Arm results'!$F$2:$F$201,$A8,'Arm results'!$D$2:$D$201,"A1",'Arm results'!$N$2:$N$201,"SUCCEEDED") | F8: 9 | G8: 4 | H8: 5 | I8: =F8/G8 | J8: =AVERAGEIFS(Paired!$L$2:$L$101,Paired!$D$2:$D$101,$A8,Paired!$H$2:$H$101,1) | K8: =EXP(J8) | L8: 1.545289 | M8: 1.5755734 | N8: 1.6250161 | O8: =AVERAGEIFS(Paired!$R$2:$R$101,Paired!$D$2:$D$101,$A8,Paired!$H$2:$H$101,1) | P8: =EXP(O8) | Q8: 1.0602487 | R8: =AVERAGEIFS('Arm results'!$O$2:$O$201,'Arm results'!$F$2:$F$201,$A8,'Arm results'!$D$2:$D$201,"B0",'Arm results'!$N$2:$N$201,"SUCCEEDED") | S8: =AVERAGEIFS('Arm results'!$O$2:$O$201,'Arm results'!$F$2:$F$201,$A8,'Arm results'!$D$2:$D$201,"A1",'Arm results'!$N$2:$N$201,"SUCCEEDED") | T8: =SUMIFS('Arm results'!$AJ$2:$AJ$201,'Arm results'!$F$2:$F$201,$A8,'Arm results'!$D$2:$D$201,"B0") | U8: =SUMIFS('Arm results'!$AJ$2:$AJ$201,'Arm results'!$F$2:$F$201,$A8,'Arm results'!$D$2:$D$201,"A1") | V8: =T8/B8 | W8: =U8/B8 | X8: =SUMIFS('Arm results'!$H$2:$H$201,'Arm results'!$F$2:$F$201,$A8,'Arm results'!$D$2:$D$201,"B0") | Y8: =SUMIFS('Arm results'!$I$2:$I$201,'Arm results'!$F$2:$F$201,$A8,'Arm results'!$D$2:$D$201,"B0")
A9: med2 | B9: =COUNTIF(Paired!$D$2:$D$101,$A9) | C9: =SUMIFS(Paired!$H$2:$H$101,Paired!$D$2:$D$101,$A9) | D9: =COUNTIFS('Arm results'!$F$2:$F$201,$A9,'Arm results'!$D$2:$D$201,"B0",'Arm results'!$N$2:$N$201,"SUCCEEDED") | E9: =COUNTIFS('Arm results'!$F$2:$F$201,$A9,'Arm results'!$D$2:$D$201,"A1",'Arm results'!$N$2:$N$201,"SUCCEEDED") | F9: 9 | G9: 4 | H9: 5 | I9: =F9/G9 | J9: =AVERAGEIFS(Paired!$L$2:$L$101,Paired!$D$2:$D$101,$A9,Paired!$H$2:$H$101,1) | K9: =EXP(J9) | L9: 1.5878379 | M9: 1.5215907 | N9: 1.6120587 | O9: =AVERAGEIFS(Paired!$R$2:$R$101,Paired!$D$2:$D$101,$A9,Paired!$H$2:$H$101,1) | P9: =EXP(O9) | Q9: 0.96770397 | R9: =AVERAGEIFS('Arm results'!$O$2:$O$201,'Arm results'!$F$2:$F$201,$A9,'Arm results'!$D$2:$D$201,"B0",'Arm results'!$N$2:$N$201,"SUCCEEDED") | S9: =AVERAGEIFS('Arm results'!$O$2:$O$201,'Arm results'!$F$2:$F$201,$A9,'Arm results'!$D$2:$D$201,"A1",'Arm results'!$N$2:$N$201,"SUCCEEDED") | T9: =SUMIFS('Arm results'!$AJ$2:$AJ$201,'Arm results'!$F$2:$F$201,$A9,'Arm results'!$D$2:$D$201,"B0") | U9: =SUMIFS('Arm results'!$AJ$2:$AJ$201,'Arm results'!$F$2:$F$201,$A9,'Arm results'!$D$2:$D$201,"A1") | V9: =T9/B9 | W9: =U9/B9 | X9: =SUMIFS('Arm results'!$H$2:$H$201,'Arm results'!$F$2:$F$201,$A9,'Arm results'!$D$2:$D$201,"B0") | Y9: =SUMIFS('Arm results'!$I$2:$I$201,'Arm results'!$F$2:$F$201,$A9,'Arm results'!$D$2:$D$201,"B0")
A10: med3 | B10: =COUNTIF(Paired!$D$2:$D$101,$A10) | C10: =SUMIFS(Paired!$H$2:$H$101,Paired!$D$2:$D$101,$A10) | D10: =COUNTIFS('Arm results'!$F$2:$F$201,$A10,'Arm results'!$D$2:$D$201,"B0",'Arm results'!$N$2:$N$201,"SUCCEEDED") | E10: =COUNTIFS('Arm results'!$F$2:$F$201,$A10,'Arm results'!$D$2:$D$201,"A1",'Arm results'!$N$2:$N$201,"SUCCEEDED") | F10: 11 | G10: 6 | H10: 2 | I10: =F10/G10 | J10: =AVERAGEIFS(Paired!$L$2:$L$101,Paired!$D$2:$D$101,$A10,Paired!$H$2:$H$101,1) | K10: =EXP(J10) | L10: 1.7250596 | M10: 1.6250201 | N10: 1.7115809 | O10: =AVERAGEIFS(Paired!$R$2:$R$101,Paired!$D$2:$D$101,$A10,Paired!$H$2:$H$101,1) | P10: =EXP(O10) | Q10: 0.9962088 | R10: =AVERAGEIFS('Arm results'!$O$2:$O$201,'Arm results'!$F$2:$F$201,$A10,'Arm results'!$D$2:$D$201,"B0",'Arm results'!$N$2:$N$201,"SUCCEEDED") | S10: =AVERAGEIFS('Arm results'!$O$2:$O$201,'Arm results'!$F$2:$F$201,$A10,'Arm results'!$D$2:$D$201,"A1",'Arm results'!$N$2:$N$201,"SUCCEEDED") | T10: =SUMIFS('Arm results'!$AJ$2:$AJ$201,'Arm results'!$F$2:$F$201,$A10,'Arm results'!$D$2:$D$201,"B0") | U10: =SUMIFS('Arm results'!$AJ$2:$AJ$201,'Arm results'!$F$2:$F$201,$A10,'Arm results'!$D$2:$D$201,"A1") | V10: =T10/B10 | W10: =U10/B10 | X10: =SUMIFS('Arm results'!$H$2:$H$201,'Arm results'!$F$2:$F$201,$A10,'Arm results'!$D$2:$D$201,"B0") | Y10: =SUMIFS('Arm results'!$I$2:$I$201,'Arm results'!$F$2:$F$201,$A10,'Arm results'!$D$2:$D$201,"B0")
A11: med4 | B11: =COUNTIF(Paired!$D$2:$D$101,$A11) | C11: =SUMIFS(Paired!$H$2:$H$101,Paired!$D$2:$D$101,$A11) | D11: =COUNTIFS('Arm results'!$F$2:$F$201,$A11,'Arm results'!$D$2:$D$201,"B0",'Arm results'!$N$2:$N$201,"SUCCEEDED") | E11: =COUNTIFS('Arm results'!$F$2:$F$201,$A11,'Arm results'!$D$2:$D$201,"A1",'Arm results'!$N$2:$N$201,"SUCCEEDED") | F11: 6 | G11: 5 | H11: 2 | I11: =F11/G11 | J11: =AVERAGEIFS(Paired!$L$2:$L$101,Paired!$D$2:$D$101,$A11,Paired!$H$2:$H$101,1) | K11: =EXP(J11) | L11: 1.1507492 | M11: 1.0651774 | N11: 1.0714576 | O11: =AVERAGEIFS(Paired!$R$2:$R$101,Paired!$D$2:$D$101,$A11,Paired!$H$2:$H$101,1) | P11: =EXP(O11) | Q11: 0.98829041 | R11: =AVERAGEIFS('Arm results'!$O$2:$O$201,'Arm results'!$F$2:$F$201,$A11,'Arm results'!$D$2:$D$201,"B0",'Arm results'!$N$2:$N$201,"SUCCEEDED") | S11: =AVERAGEIFS('Arm results'!$O$2:$O$201,'Arm results'!$F$2:$F$201,$A11,'Arm results'!$D$2:$D$201,"A1",'Arm results'!$N$2:$N$201,"SUCCEEDED") | T11: =SUMIFS('Arm results'!$AJ$2:$AJ$201,'Arm results'!$F$2:$F$201,$A11,'Arm results'!$D$2:$D$201,"B0") | U11: =SUMIFS('Arm results'!$AJ$2:$AJ$201,'Arm results'!$F$2:$F$201,$A11,'Arm results'!$D$2:$D$201,"A1") | V11: =T11/B11 | W11: =U11/B11 | X11: =SUMIFS('Arm results'!$H$2:$H$201,'Arm results'!$F$2:$F$201,$A11,'Arm results'!$D$2:$D$201,"B0") | Y11: =SUMIFS('Arm results'!$I$2:$I$201,'Arm results'!$F$2:$F$201,$A11,'Arm results'!$D$2:$D$201,"B0")
A12: All | B12: =SUM(B2:B11) | C12: =SUM(C2:C11) | D12: =SUM(D2:D11) | E12: =SUM(E2:E11) | J12: =AVERAGE(J2:J11) | K12: =EXP(J12) | O12: =AVERAGE(O2:O11) | P12: =EXP(O12) | T12: =SUM(T2:T11) | U12: =SUM(U2:U11) | V12: =T12/B12 | W12: =U12/B12 | X12: =SUM(X2:X11) | Y12: =SUM(Y2:Y11)
A14: Row 'All': S = exp(mean of template mean ln speedups) = the pre-registered primary estimate (equal weight per template). Speedups use only tasks where both arms succeeded; mean T_exec uses succeeded arms only; accuracy counts a failed arm as incorrect. '(script)' columns: Source: data/cohort100_ab/analysis/eval.json (cohort100_ab_analyze.py, unchanged, --runs eval-b1 eval-b2 --decompose dec-1)

Sheet Estimates
A1: Section | B1: Estimate | C1: Value | D1: 95% CI low | E1: 95% CI high | F1: n tasks | G1: n templates | H1: Workbook check | I1: Note
A2: §4 | B2: Primary S — geometric-mean speedup, equal weight per template | C2: 1.282703 | D2: 1.2246418 | E2: 1.3442719 | F2: 99 | G2: 10 | H2: =Templates!$K$12 | I2: H1 supported: CI lower bound > 1
A3: §4 | B3: Latency reduction 1 - 1/S | C3: 0.22039629 | H3: =1-1/Templates!$K$12
A4: §4 | B4: Task-pooled geometric mean (equal weight per task) | C4: 1.2654182 | F4: 99 | H4: =EXP(AVERAGEIFS(Paired!$L$2:$L$101,Paired!$H$2:$H$101,1))
A5: §4 | B5: PDF latency reduction (T_B0 - T_A1)/T_B0, template-weighted mean | C5: 0.18640913
A6: §5.1 | B6: Replay speedup, dependency schedule (B0 durations) | C6: 1.3157036 | D6: 1.2993534 | E6: 1.3315068 | F6: 99 | G6: 10 | I6: Used for H2
A7: §5.1 | B7: Replay speedup, dependency schedule (A1 durations) | C7: 1.3252267 | D7: 1.3064367 | E7: 1.3441856 | F7: 99 | G7: 10
A8: §5.2 | B8: Replay speedup, wave-barrier schedule (B0 durations) | C8: 1.2233495 | F8: 99 | G8: 10
A9: §5.2 | B9: Replay speedup, wave-barrier schedule (A1 durations) | C9: 1.2303008 | F9: 99 | G9: 10
A10: §5.2 | B10: Wave-barrier loss (template mean), B0 durations | C10: 0.067359289 | I10: (barrier time - dependency CP) / barrier time
A11: §5.2 | B11: Wave-barrier loss (template mean), A1 durations | C11: 0.06858699
A12: §5.3 | B12: Orchestration overhead A1 (s, template mean) | C12: 3.6679244 | I12: T_exec - replay CP (A1 durations)
A13: §5.3 | B13: Orchestration overhead B0 (s, template mean) | C13: 3.162526 | I13: T_exec - sum of B0 node durations
A14: §5.4 | B14: Speedup including T_dec (B0 + T_dec) / (A1 + T_dec) | C14: 1.2771829 | D14: 1.2201757 | E14: 1.3377308 | F14: 99 | G14: 10 | H14: =Templates!$P$12 | I14: T_dec from dec-1 (deviations D1, D5)
A15: §5.4 | B15: Mean T_dec (s), tasks where both arms succeeded | C15: 2.5516254 | F15: 99 | H15: =AVERAGEIFS(Paired!$O$2:$O$101,Paired!$H$2:$H$101,1)
A16: §5.4 | B16: Returned DAG exactly matches the dataset DAG (share of 100) | C16: 0.69 | F16: 100 | H16: =AVERAGE(Paired!$P$2:$P$101) | I16: LongCoT prompts list their subproblems: T_dec is a lower bound (prereg §12.2)
A17: §5.5 | B17: C_LLM ratio A1/B0 (geo-mean, template-weighted) | C17: 1.0300796 | F17: 99 | G17: 10
A18: §5.5 | B18: C_Total ratio A1/B0 (geo-mean, template-weighted) | C18: 1.0407024 | F18: 99 | G18: 10
A19: §2 H2 | B19: Spearman: template S vs replay (B0) | C19: 0.86666667 | G19: 10 | I19: Descriptive only (10 templates)
A20: §2 H2 | B20: Spearman: template S vs N/D | C20: 0.81348989 | G20: 10 | I20: Descriptive only
A21: §6.1 | B21: S, cold-start adjusted | C21: 1.2822614 | F21: 99 | G21: 10
A22: §6.2 | B22: S without exposed tasks | C22: 1.3147054 | F22: 66 | G22: 8 | I22: Drops most easy tasks: template mix changes
A23: §6.2 | B23: S without flagged-impossible tasks | C23: 1.2916658 | F23: 83 | G23: 10
A24: §6.2 | B24: S without easy2-policy tasks | C24: 1.3127318 | F24: 84 | G24: 9
A25: §6.3 | B25: S, B0-first tasks | C25: 1.3570452 | F25: 50 | G25: 10 | I25: Order split 50/49; gap seen in both batches
